<?xml version="1.0" ?>
<robot name="h1_box">
  <link name="R_hand_base_link">
    <inertial>
      <origin xyz="0 0 0" rpy="0 0 0"/>
      <mass value="0.14143"/>
      <inertia ixx="1.473229e-04" ixy="0.000000e+00" ixz="0.000000e+00" iyy="3.064317e-05" iyz="0.000000e+00" izz="1.190369e-04"/>
    </inertial>
    <visual>
      <origin xyz="-0.005000 -0.050000 0.000000" rpy="0.000000 0.000000 0.000000"/>
      <geometry>
        <box size="0.01 0.1 0.05"/>
      </geometry>
    </visual>
    <collision>
      <origin xyz="-0.005000 -0.050000 0.000000" rpy="0.000000 0.000000 0.000000"/>
      <geometry>
        <box size="0.01 0.1 0.05"/>
      </geometry>
    </collision>
  </link>
  <link name="R_thumb_proximal_base">
    <inertial>
      <origin xyz="0 0 0" rpy="0 0 0"/>
      <mass value="0.0018869"/>
      <inertia ixx="6.003683e-08" ixy="0.000000e+00" ixz="0.000000e+00" iyy="3.144833e-08" iyz="0.000000e+00" izz="6.003683e-08"/>
    </inertial>
    <visual>
      <origin xyz="0.000100 0.010900 -0.001400" rpy="0.000000 0.583600 3.821700"/>
      <geometry>
        <box size="0.01 0.016787272024066328 0.01"/>
      </geometry>
    </visual>
    <collision>
      <origin xyz="0.000100 0.010900 -0.001400" rpy="0.000000 0.583600 3.821700"/>
      <geometry>
        <box size="0.01 0.016787272024066328 0.01"/>
      </geometry>
    </collision>
  </link>
  <link name="R_thumb_proximal">
    <inertial>
      <origin xyz="0 0 0" rpy="0 0 0"/>
      <mass value="0.0066075"/>
      <inertia ixx="1.782216e-06" ixy="0.000000e+00" ixz="0.000000e+00" iyy="1.101250e-07" iyz="0.000000e+00" izz="1.782216e-06"/>
    </inertial>
    <visual>
      <origin xyz="0.025200 0.013300 -0.004900" rpy="0.000000 0.014300 2.235700"/>
      <geometry>
        <box size="0.01 0.056006380966814845 0.01"/>
      </geometry>
    </visual>
    <collision>
      <origin xyz="0.025200 0.013300 -0.004900" rpy="0.000000 0.014300 2.235700"/>
      <geometry>
        <box size="0.01 0.056006380966814845 0.01"/>
      </geometry>
    </collision>
  </link>
  <link name="R_thumb_intermediate">
    <inertial>
      <origin xyz="0 0 0" rpy="0 0 0"/>
      <mass value="0.0037847"/>
      <inertia ixx="1.938289e-07" ixy="0.000000e+00" ixz="0.000000e+00" iyy="6.307833e-08" iyz="0.000000e+00" izz="1.938289e-07"/>
    </inertial>
    <visual>
      <origin xyz="0.012500 0.000400 -0.004700" rpy="0.000000 0.052900 2.035700"/>
      <geometry>
        <box size="0.01 0.02268404373122217 0.01"/>
      </geometry>
    </visual>
    <collision>
      <origin xyz="0.012500 0.000400 -0.004700" rpy="0.000000 0.052900 2.035700"/>
      <geometry>
        <box size="0.01 0.02268404373122217 0.01"/>
      </geometry>
    </collision>
  </link>
  <link name="R_thumb_distal">
    <inertial>
      <origin xyz="0 0 0" rpy="0 0 0"/>
      <mass value="0.0033441"/>
      <inertia ixx="1.762956e-07" ixy="0.000000e+00" ixz="0.000000e+00" iyy="5.573500e-08" iyz="0.000000e+00" izz="1.762956e-07"/>
    </inertial>
    <visual>
      <origin xyz="0.012500 0.003700 -0.003500" rpy="0.000000 0.262600 2.346600"/>
      <geometry>
        <box size="0.01 0.023078574950895474 0.01"/>
      </geometry>
    </visual>
    <collision>
      <origin xyz="0.012500 0.003700 -0.003500" rpy="0.000000 0.262600 2.346600"/>
      <geometry>
        <box size="0.01 0.023078574950895474 0.01"/>
      </geometry>
    </collision>
  </link>
  <link name="R_thumb_tip">
    <visual>
      <origin xyz="0 0 0" rpy="0 0 0"/>
      <geometry>
        <sphere radius="0.007"/>
      </geometry>
    </visual>
  </link>
  <link name="R_index_proximal">
    <inertial>
      <origin xyz="0 0 0" rpy="0 0 0"/>
      <mass value="0.0042403"/>
      <inertia ixx="4.005303e-07" ixy="0.000000e+00" ixz="0.000000e+00" iyy="7.067167e-08" iyz="0.000000e+00" izz="4.005303e-07"/>
    </inertial>
    <visual>
      <origin xyz="-0.005000 0.016100 -0.005000" rpy="0.000000 0.000000 0.000000"/>
      <geometry>
        <box size="0.01 0.03214803454972014 0.01"/>
      </geometry>
    </visual>
    <collision>
      <origin xyz="-0.005000 0.016100 -0.005000" rpy="0.000000 0.000000 0.000000"/>
      <geometry>
        <box size="0.01 0.03214803454972014 0.01"/>
      </geometry>
    </collision>
  </link>
  <link name="R_index_intermediate">
    <inertial>
      <origin xyz="0 0 0" rpy="0 0 0"/>
      <mass value="0.0045683"/>
      <inertia ixx="7.682803e-07" ixy="0.000000e+00" ixz="0.000000e+00" iyy="7.613833e-08" iyz="0.000000e+00" izz="7.682803e-07"/>
    </inertial>
    <visual>
      <origin xyz="-0.005000 0.021900 -0.005000" rpy="0.000000 0.000000 0.000000"/>
      <geometry>
        <box size="0.01 0.04379631116135011 0.01"/>
      </geometry>
    </visual>
    <collision>
      <origin xyz="-0.005000 0.021900 -0.005000" rpy="0.000000 0.000000 0.000000"/>
      <geometry>
        <box size="0.01 0.04379631116135011 0.01"/>
      </geometry>
    </collision>
  </link>
  <link name="R_index_tip">
    <visual>
      <origin xyz="0 0 0" rpy="0 0 0"/>
      <geometry>
        <sphere radius="0.007"/>
      </geometry>
    </visual>
  </link>
  <link name="R_middle_proximal">
    <inertial>
      <origin xyz="0 0 0" rpy="0 0 0"/>
      <mass value="0.0042403"/>
      <inertia ixx="4.005303e-07" ixy="0.000000e+00" ixz="0.000000e+00" iyy="7.067167e-08" iyz="0.000000e+00" izz="4.005303e-07"/>
    </inertial>
    <visual>
      <origin xyz="-0.005000 0.016100 -0.005000" rpy="0.000000 0.000000 0.000000"/>
      <geometry>
        <box size="0.01 0.03214803454972014 0.01"/>
      </geometry>
    </visual>
    <collision>
      <origin xyz="-0.005000 0.016100 -0.005000" rpy="0.000000 0.000000 0.000000"/>
      <geometry>
        <box size="0.01 0.03214803454972014 0.01"/>
      </geometry>
    </collision>
  </link>
  <link name="R_middle_intermediate">
    <inertial>
      <origin xyz="0 0 0" rpy="0 0 0"/>
      <mass value="0.0050396"/>
      <inertia ixx="9.722444e-07" ixy="0.000000e+00" ixz="0.000000e+00" iyy="8.399333e-08" iyz="0.000000e+00" izz="9.722444e-07"/>
    </inertial>
    <visual>
      <origin xyz="-0.005000 0.023500 -0.005000" rpy="0.000000 0.000000 0.000000"/>
      <geometry>
        <box size="0.01 0.04706433173139187 0.01"/>
      </geometry>
    </visual>
    <collision>
      <origin xyz="-0.005000 0.023500 -0.005000" rpy="0.000000 0.000000 0.000000"/>
      <geometry>
        <box size="0.01 0.04706433173139187 0.01"/>
      </geometry>
    </collision>
  </link>
  <link name="R_middle_tip">
    <visual>
      <origin xyz="0 0 0" rpy="0 0 0"/>
      <geometry>
        <sphere radius="0.007"/>
      </geometry>
    </visual>
  </link>
  <link name="R_ring_proximal">
    <inertial>
      <origin xyz="0 0 0" rpy="0 0 0"/>
      <mass value="0.0042403"/>
      <inertia ixx="4.005303e-07" ixy="0.000000e+00" ixz="0.000000e+00" iyy="7.067167e-08" iyz="0.000000e+00" izz="4.005303e-07"/>
    </inertial>
    <visual>
      <origin xyz="-0.005000 0.016100 -0.005000" rpy="0.000000 0.000000 0.000000"/>
      <geometry>
        <box size="0.01 0.03214803454972014 0.01"/>
      </geometry>
    </visual>
    <collision>
      <origin xyz="-0.005000 0.016100 -0.005000" rpy="0.000000 0.000000 0.000000"/>
      <geometry>
        <box size="0.01 0.03214803454972014 0.01"/>
      </geometry>
    </collision>
  </link>
  <link name="R_ring_intermediate">
    <inertial>
      <origin xyz="0 0 0" rpy="0 0 0"/>
      <mass value="0.0045683"/>
      <inertia ixx="7.682811e-07" ixy="0.000000e+00" ixz="0.000000e+00" iyy="7.613833e-08" iyz="0.000000e+00" izz="7.682811e-07"/>
    </inertial>
    <visual>
      <origin xyz="-0.005000 0.021900 -0.005000" rpy="0.000000 0.000000 0.000000"/>
      <geometry>
        <box size="0.01 0.04379633523392682 0.01"/>
      </geometry>
    </visual>
    <collision>
      <origin xyz="-0.005000 0.021900 -0.005000" rpy="0.000000 0.000000 0.000000"/>
      <geometry>
        <box size="0.01 0.04379633523392682 0.01"/>
      </geometry>
    </collision>
  </link>
  <link name="R_ring_tip">
    <visual>
      <origin xyz="0 0 0" rpy="0 0 0"/>
      <geometry>
        <sphere radius="0.007"/>
      </geometry>
    </visual>
  </link>
  <link name="R_pinky_proximal">
    <inertial>
      <origin xyz="0 0 0" rpy="0 0 0"/>
      <mass value="0.0042403"/>
      <inertia ixx="4.005303e-07" ixy="0.000000e+00" ixz="0.000000e+00" iyy="7.067167e-08" iyz="0.000000e+00" izz="4.005303e-07"/>
    </inertial>
    <visual>
      <origin xyz="-0.005000 0.016100 -0.005000" rpy="0.000000 0.000000 0.000000"/>
      <geometry>
        <box size="0.01 0.03214803454972014 0.01"/>
      </geometry>
    </visual>
    <collision>
      <origin xyz="-0.005000 0.016100 -0.005000" rpy="0.000000 0.000000 0.000000"/>
      <geometry>
        <box size="0.01 0.03214803454972014 0.01"/>
      </geometry>
    </collision>
  </link>
  <link name="R_pinky_intermediate">
    <inertial>
      <origin xyz="0 0 0" rpy="0 0 0"/>
      <mass value="0.0035996"/>
      <inertia ixx="4.343419e-07" ixy="0.000000e+00" ixz="0.000000e+00" iyy="5.999333e-08" iyz="0.000000e+00" izz="4.343419e-07"/>
    </inertial>
    <visual>
      <origin xyz="-0.005000 0.018400 -0.005000" rpy="0.000000 0.000000 0.000000"/>
      <geometry>
        <box size="0.01 0.03671467408620836 0.01"/>
      </geometry>
    </visual>
    <collision>
      <origin xyz="-0.005000 0.018400 -0.005000" rpy="0.000000 0.000000 0.000000"/>
      <geometry>
        <box size="0.01 0.03671467408620836 0.01"/>
      </geometry>
    </collision>
  </link>
  <link name="R_pinky_tip">
    <visual>
      <origin xyz="0 0 0" rpy="0 0 0"/>
      <geometry>
        <sphere radius="0.007"/>
      </geometry>
    </visual>
  </link>
  <joint name="R_thumb_proximal_yaw" type="revolute">
    <origin xyz="-0.016960 -0.069100 -0.020450" rpy="1.570800 -1.570800 0.000000"/>
    <parent link="R_hand_base_link"/>
    <child link="R_thumb_proximal_base"/>
    <axis xyz="0 0 -1"/>
    <limit lower="-0.1" upper="1.3" effort="1" velocity="0.5"/>
  </joint>
  <joint name="R_thumb_proximal_pitch" type="revolute">
    <origin xyz="-0.008810 0.010892 -0.009250" rpy="1.570800 0.000000 2.858700"/>
    <parent link="R_thumb_proximal_base"/>
    <child link="R_thumb_proximal"/>
    <axis xyz="0 0 1"/>
    <limit lower="0.0" upper="0.5" effort="1" velocity="0.5"/>
  </joint>
  <joint name="R_thumb_intermediate" type="revolute">
    <origin xyz="0.044070 0.034553 -0.000800" rpy="0.000000 0.000000 0.000000"/>
    <parent link="R_thumb_proximal"/>
    <child link="R_thumb_intermediate"/>
    <axis xyz="0 0 1"/>
    <limit lower="0" upper="0.8" effort="1" velocity="0.5"/>
    <mimic joint="R_thumb_proximal_pitch" multiplier="1.6" offset="0"/>
  </joint>
  <joint name="R_thumb_distal" type="revolute">
    <origin xyz="0.020248 0.010156 -0.001200" rpy="0.000000 0.000000 0.000000"/>
    <parent link="R_thumb_intermediate"/>
    <child link="R_thumb_distal"/>
    <axis xyz="0 0 1"/>
    <limit lower="0" upper="1.2" effort="1" velocity="0.5"/>
    <mimic joint="R_thumb_proximal_pitch" multiplier="2.4" offset="0"/>
  </joint>
  <joint name="R_thumb_tip_joint" type="fixed">
    <parent link="R_thumb_distal"/>
    <child link="R_thumb_tip"/>
    <origin xyz="0.020000 0.012000 -0.002000" rpy="0.000000 0.000000 0.000000"/>
  </joint>
  <joint name="R_index_proximal" type="revolute">
    <origin xyz="0.000285 -0.136530 -0.032268" rpy="-3.106700 0.000000 0.000000"/>
    <parent link="R_hand_base_link"/>
    <child link="R_index_proximal"/>
    <axis xyz="0 0 1"/>
    <limit lower="0" upper="1.7" effort="1" velocity="0.5"/>
  </joint>
  <joint name="R_index_intermediate" type="revolute">
    <origin xyz="0.000000 0.032026 0.000000" rpy="0.000000 0.000000 0.000000"/>
    <parent link="R_index_proximal"/>
    <child link="R_index_intermediate"/>
    <axis xyz="0 0 1"/>
    <limit lower="0" upper="1.7" effort="1" velocity="0.5"/>
    <mimic joint="R_index_proximal" multiplier="1" offset="0"/>
  </joint>
  <joint name="R_index_tip_joint" type="fixed">
    <parent link="R_index_intermediate"/>
    <child link="R_index_tip"/>
    <origin xyz="-0.005000 0.043313 -0.005000" rpy="0.000000 0.000000 0.000000"/>
  </joint>
  <joint name="R_middle_proximal" type="revolute">
    <origin xyz="0.000285 -0.137100 -0.012950" rpy="-3.141600 0.000000 0.000000"/>
    <parent link="R_hand_base_link"/>
    <child link="R_middle_proximal"/>
    <axis xyz="0 0 1"/>
    <limit lower="0" upper="1.7" effort="1" velocity="0.5"/>
  </joint>
  <joint name="R_middle_intermediate" type="revolute">
    <origin xyz="0.000000 0.032041 0.000000" rpy="0.000000 0.000000 0.000000"/>
    <parent link="R_middle_proximal"/>
    <child link="R_middle_intermediate"/>
    <axis xyz="0 0 1"/>
    <limit lower="0" upper="1.7" effort="1" velocity="0.5"/>
    <mimic joint="R_middle_proximal" multiplier="1" offset="0"/>
  </joint>
  <joint name="R_middle_tip_joint" type="fixed">
    <parent link="R_middle_intermediate"/>
    <child link="R_middle_tip"/>
    <origin xyz="-0.005000 0.046604 -0.005000" rpy="0.000000 0.000000 0.000000"/>
  </joint>
  <joint name="R_ring_proximal" type="revolute">
    <origin xyz="0.000285 -0.136910 0.006287" rpy="3.089200 0.000000 0.000000"/>
    <parent link="R_hand_base_link"/>
    <child link="R_ring_proximal"/>
    <axis xyz="0 0 1"/>
    <limit lower="0" upper="1.7" effort="1" velocity="0.5"/>
  </joint>
  <joint name="R_ring_intermediate" type="revolute">
    <origin xyz="0.000000 0.032041 0.000000" rpy="0.000000 0.000000 0.000000"/>
    <parent link="R_ring_proximal"/>
    <child link="R_ring_intermediate"/>
    <axis xyz="0 0 1"/>
    <limit lower="0" upper="1.7" effort="1" velocity="0.5"/>
    <mimic joint="R_ring_proximal" multiplier="1" offset="0"/>
  </joint>
  <joint name="R_ring_tip_joint" type="fixed">
    <parent link="R_ring_intermediate"/>
    <child link="R_ring_tip"/>
    <origin xyz="-0.005000 0.043354 -0.005000" rpy="0.000000 0.000000 0.000000"/>
  </joint>
  <joint name="R_pinky_proximal" type="revolute">
    <origin xyz="0.000285 -0.135710 0.025488" rpy="3.036900 0.000000 0.000000"/>
    <parent link="R_hand_base_link"/>
    <child link="R_pinky_proximal"/>
    <axis xyz="0 0 1"/>
    <limit lower="0" upper="1.7" effort="1" velocity="0.5"/>
  </joint>
  <joint name="R_pinky_intermediate" type="revolute">
    <origin xyz="0.000000 0.032041 0.000000" rpy="0.000000 0.000000 0.000000"/>
    <parent link="R_pinky_proximal"/>
    <child link="R_pinky_intermediate"/>
    <axis xyz="0 0 1"/>
    <limit lower="0" upper="1.7" effort="1" velocity="0.5"/>
    <mimic joint="R_pinky_proximal" multiplier="1" offset="0"/>
  </joint>
  <joint name="R_pinky_tip_joint" type="fixed">
    <parent link="R_pinky_intermediate"/>
    <child link="R_pinky_tip"/>
    <origin xyz="-0.005000 0.036278 -0.005000" rpy="0.000000 0.000000 0.000000"/>
  </joint>
</robot>
